Workbook

Sheet Dashboard
A1: Senior FDE Master Plan: 600 hours, 9 months
A2: Twelve tracks, three vetted resources per topic (read, watch, do), every Scaler module covered plus the production and interview layers Scaler does not teach. Edit only yellow cells and the two blue inputs.
A4: Inputs
A5: Weekly hours you will actually commit | B5: 16
A6: Current month (1-9) | B6: 1
A8: Overall
A9: Topics in plan | B9: =COUNTA(Plan!A2:A400) -> 81
A10: Skipped (optional deep dives) | B10: =COUNTIF(Plan!P2:P400,"Skipped") -> 2
A11: Done | B11: =COUNTIF(Plan!P2:P400,"Done") -> 0
A12: In progress | B12: =COUNTIF(Plan!P2:P400,"In progress") -> 0
A13: Progress (done / not skipped) | B13: =IF((B9-B10)=0,0,B11/(B9-B10)) -> 0
A14: Hours planned (excluding skipped) | B14: =SUMIF(Plan!P2:P400,"<>Skipped",Plan!N2:N400) -> 612
A15: Hours done | B15: =SUMIF(Plan!P2:P400,"Done",Plan!N2:N400) -> 0
A16: Hours remaining | B16: =B14-B15 -> 612
A17: Weeks remaining at your weekly hours | B17: =IF(B5=0,0,B16/B5) -> 38.25
A18: Months remaining at your weekly hours | B18: =B17/4.33 -> 8.8337182
A19: Topics scheduled for the current month | B19: =COUNTIF(Plan!B2:B400,B6) -> 8
A20: Hours scheduled for the current month | B20: =SUMIFS(Plan!N2:N400,Plan!B2:B400,B6,Plan!P2:P400,"<>Skipped") -> 60
A21: Mocks done / target | B21: =Mocks!G13&" / "&Mocks!B13 -> 0 / 57
A23: By track
A24: Track | B24: Topics | C24: Done | D24: Skipped | E24: Progress | F24: Hours planned | G24: Hours done | H24: Hours left
A25: A. Linux, Networking, Shell | B25: =COUNTIF(Plan!$A$2:$A$400,A25) -> 5 | C25: =COUNTIFS(Plan!$A$2:$A$400,A25,Plan!$P$2:$P$400,"Done") -> 0 | D25: =COUNTIFS(Plan!$A$2:$A$400,A25,Plan!$P$2:$P$400,"Skipped") -> 0 | E25: =IF((B25-D25)=0,0,C25/(B25-D25)) -> 0 | F25: =SUMIFS(Plan!$N$2:$N$400,Plan!$A$2:$A$400,A25,Plan!$P$2:$P$400,"<>Skipped") -> 34 | G25: =SUMIFS(Plan!$N$2:$N$400,Plan!$A$2:$A$400,A25,Plan!$P$2:$P$400,"Done") -> 0 | H25: =F25-G25 -> 34
A26: B. Containers and Kubernetes | B26: =COUNTIF(Plan!$A$2:$A$400,A26) -> 7 | C26: =COUNTIFS(Plan!$A$2:$A$400,A26,Plan!$P$2:$P$400,"Done") -> 0 | D26: =COUNTIFS(Plan!$A$2:$A$400,A26,Plan!$P$2:$P$400,"Skipped") -> 0 | E26: =IF((B26-D26)=0,0,C26/(B26-D26)) -> 0 | F26: =SUMIFS(Plan!$N$2:$N$400,Plan!$A$2:$A$400,A26,Plan!$P$2:$P$400,"<>Skipped") -> 62 | G26: =SUMIFS(Plan!$N$2:$N$400,Plan!$A$2:$A$400,A26,Plan!$P$2:$P$400,"Done") -> 0 | H26: =F26-G26 -> 62
A27: C. Cloud and IaC | B27: =COUNTIF(Plan!$A$2:$A$400,A27) -> 8 | C27: =COUNTIFS(Plan!$A$2:$A$400,A27,Plan!$P$2:$P$400,"Done") -> 0 | D27: =COUNTIFS(Plan!$A$2:$A$400,A27,Plan!$P$2:$P$400,"Skipped") -> 0 | E27: =IF((B27-D27)=0,0,C27/(B27-D27)) -> 0 | F27: =SUMIFS(Plan!$N$2:$N$400,Plan!$A$2:$A$400,A27,Plan!$P$2:$P$400,"<>Skipped") -> 55 | G27: =SUMIFS(Plan!$N$2:$N$400,Plan!$A$2:$A$400,A27,Plan!$P$2:$P$400,"Done") -> 0 | H27: =F27-G27 -> 55
A28: D. Reliability and Observability | B28: =COUNTIF(Plan!$A$2:$A$400,A28) -> 5 | C28: =COUNTIFS(Plan!$A$2:$A$400,A28,Plan!$P$2:$P$400,"Done") -> 0 | D28: =COUNTIFS(Plan!$A$2:$A$400,A28,Plan!$P$2:$P$400,"Skipped") -> 0 | E28: =IF((B28-D28)=0,0,C28/(B28-D28)) -> 0 | F28: =SUMIFS(Plan!$N$2:$N$400,Plan!$A$2:$A$400,A28,Plan!$P$2:$P$400,"<>Skipped") -> 34 | G28: =SUMIFS(Plan!$N$2:$N$400,Plan!$A$2:$A$400,A28,Plan!$P$2:$P$400,"Done") -> 0 | H28: =F28-G28 -> 34
A29: E. Backend and Data | B29: =COUNTIF(Plan!$A$2:$A$400,A29) -> 12 | C29: =COUNTIFS(Plan!$A$2:$A$400,A29,Plan!$P$2:$P$400,"Done") -> 0 | D29: =COUNTIFS(Plan!$A$2:$A$400,A29,Plan!$P$2:$P$400,"Skipped") -> 1 | E29: =IF((B29-D29)=0,0,C29/(B29-D29)) -> 0 | F29: =SUMIFS(Plan!$N$2:$N$400,Plan!$A$2:$A$400,A29,Plan!$P$2:$P$400,"<>Skipped") -> 84 | G29: =SUMIFS(Plan!$N$2:$N$400,Plan!$A$2:$A$400,A29,Plan!$P$2:$P$400,"Done") -> 0 | H29: =F29-G29 -> 84
A30: F. Distributed Systems and System Design | B30: =COUNTIF(Plan!$A$2:$A$400,A30) -> 6 | C30: =COUNTIFS(Plan!$A$2:$A$400,A30,Plan!$P$2:$P$400,"Done") -> 0 | D30: =COUNTIFS(Plan!$A$2:$A$400,A30,Plan!$P$2:$P$400,"Skipped") -> 1 | E30: =IF((B30-D30)=0,0,C30/(B30-D30)) -> 0 | F30: =SUMIFS(Plan!$N$2:$N$400,Plan!$A$2:$A$400,A30,Plan!$P$2:$P$400,"<>Skipped") -> 52 | G30: =SUMIFS(Plan!$N$2:$N$400,Plan!$A$2:$A$400,A30,Plan!$P$2:$P$400,"Done") -> 0 | H30: =F30-G30 -> 52
A31: G. AI Engineering | B31: =COUNTIF(Plan!$A$2:$A$400,A31) -> 8 | C31: =COUNTIFS(Plan!$A$2:$A$400,A31,Plan!$P$2:$P$400,"Done") -> 0 | D31: =COUNTIFS(Plan!$A$2:$A$400,A31,Plan!$P$2:$P$400,"Skipped") -> 0 | E31: =IF((B31-D31)=0,0,C31/(B31-D31)) -> 0 | F31: =SUMIFS(Plan!$N$2:$N$400,Plan!$A$2:$A$400,A31,Plan!$P$2:$P$400,"<>Skipped") -> 66 | G31: =SUMIFS(Plan!$N$2:$N$400,Plan!$A$2:$A$400,A31,Plan!$P$2:$P$400,"Done") -> 0 | H31: =F31-G31 -> 66
A32: H. AI in Production | B32: =COUNTIF(Plan!$A$2:$A$400,A32) -> 7 | C32: =COUNTIFS(Plan!$A$2:$A$400,A32,Plan!$P$2:$P$400,"Done") -> 0 | D32: =COUNTIFS(Plan!$A$2:$A$400,A32,Plan!$P$2:$P$400,"Skipped") -> 0 | E32: =IF((B32-D32)=0,0,C32/(B32-D32)) -> 0 | F32: =SUMIFS(Plan!$N$2:$N$400,Plan!$A$2:$A$400,A32,Plan!$P$2:$P$400,"<>Skipped") -> 50 | G32: =SUMIFS(Plan!$N$2:$N$400,Plan!$A$2:$A$400,A32,Plan!$P$2:$P$400,"Done") -> 0 | H32: =F32-G32 -> 50
A33: I. Security and Compliance | B33: =COUNTIF(Plan!$A$2:$A$400,A33) -> 5 | C33: =COUNTIFS(Plan!$A$2:$A$400,A33,Plan!$P$2:$P$400,"Done") -> 0 | D33: =COUNTIFS(Plan!$A$2:$A$400,A33,Plan!$P$2:$P$400,"Skipped") -> 0 | E33: =IF((B33-D33)=0,0,C33/(B33-D33)) -> 0 | F33: =SUMIFS(Plan!$N$2:$N$400,Plan!$A$2:$A$400,A33,Plan!$P$2:$P$400,"<>Skipped") -> 32 | G33: =SUMIFS(Plan!$N$2:$N$400,Plan!$A$2:$A$400,A33,Plan!$P$2:$P$400,"Done") -> 0 | H33: =F33-G33 -> 32
A34: J. FDE Craft and Communication | B34: =COUNTIF(Plan!$A$2:$A$400,A34) -> 6 | C34: =COUNTIFS(Plan!$A$2:$A$400,A34,Plan!$P$2:$P$400,"Done") -> 0 | D34: =COUNTIFS(Plan!$A$2:$A$400,A34,Plan!$P$2:$P$400,"Skipped") -> 0 | E34: =IF((B34-D34)=0,0,C34/(B34-D34)) -> 0 | F34: =SUMIFS(Plan!$N$2:$N$400,Plan!$A$2:$A$400,A34,Plan!$P$2:$P$400,"<>Skipped") -> 41 | G34: =SUMIFS(Plan!$N$2:$N$400,Plan!$A$2:$A$400,A34,Plan!$P$2:$P$400,"Done") -> 0 | H34: =F34-G34 -> 41
A35: K. Interview Loop and Mocks | B35: =COUNTIF(Plan!$A$2:$A$400,A35) -> 8 | C35: =COUNTIFS(Plan!$A$2:$A$400,A35,Plan!$P$2:$P$400,"Done") -> 0 | D35: =COUNTIFS(Plan!$A$2:$A$400,A35,Plan!$P$2:$P$400,"Skipped") -> 0 | E35: =IF((B35-D35)=0,0,C35/(B35-D35)) -> 0 | F35: =SUMIFS(Plan!$N$2:$N$400,Plan!$A$2:$A$400,A35,Plan!$P$2:$P$400,"<>Skipped") -> 72 | G35: =SUMIFS(Plan!$N$2:$N$400,Plan!$A$2:$A$400,A35,Plan!$P$2:$P$400,"Done") -> 0 | H35: =F35-G35 -> 72
A36: L. Portfolio, Positioning, Pipeline | B36: =COUNTIF(Plan!$A$2:$A$400,A36) -> 4 | C36: =COUNTIFS(Plan!$A$2:$A$400,A36,Plan!$P$2:$P$400,"Done") -> 0 | D36: =COUNTIFS(Plan!$A$2:$A$400,A36,Plan!$P$2:$P$400,"Skipped") -> 0 | E36: =IF((B36-D36)=0,0,C36/(B36-D36)) -> 0 | F36: =SUMIFS(Plan!$N$2:$N$400,Plan!$A$2:$A$400,A36,Plan!$P$2:$P$400,"<>Skipped") -> 30 | G36: =SUMIFS(Plan!$N$2:$N$400,Plan!$A$2:$A$400,A36,Plan!$P$2:$P$400,"Done") -> 0 | H36: =F36-G36 -> 30
A37: Total | B37: =SUM(B25:B36) -> 81 | C37: =SUM(C25:C36) -> 0 | D37: =SUM(D25:D36) -> 2 | E37: =IF((B37-D37)=0,0,C37/(B37-D37)) -> 0 | F37: =SUM(F25:F36) -> 612 | G37: =SUM(G25:G36) -> 0 | H37: =SUM(H25:H36) -> 612
A39: By month (hours planned, excluding skipped; weeks needed at your pace)
A40: Month | B40: Hours | C40: Done | D40: Weeks at your pace | E40: Over 4.33 weeks?
A41: 1 | B41: =SUMIFS(Plan!$N$2:$N$400,Plan!$B$2:$B$400,A41,Plan!$P$2:$P$400,"<>Skipped") -> 60 | C41: =SUMIFS(Plan!$N$2:$N$400,Plan!$B$2:$B$400,A41,Plan!$P$2:$P$400,"Done") -> 0 | D41: =IF($B$5=0,0,B41/$B$5) -> 3.75 | E41: =IF(D41>4.33,"Yes","")
A42: 2 | B42: =SUMIFS(Plan!$N$2:$N$400,Plan!$B$2:$B$400,A42,Plan!$P$2:$P$400,"<>Skipped") -> 79 | C42: =SUMIFS(Plan!$N$2:$N$400,Plan!$B$2:$B$400,A42,Plan!$P$2:$P$400,"Done") -> 0 | D42: =IF($B$5=0,0,B42/$B$5) -> 4.9375 | E42: =IF(D42>4.33,"Yes","") -> Yes
A43: 3 | B43: =SUMIFS(Plan!$N$2:$N$400,Plan!$B$2:$B$400,A43,Plan!$P$2:$P$400,"<>Skipped") -> 70 | C43: =SUMIFS(Plan!$N$2:$N$400,Plan!$B$2:$B$400,A43,Plan!$P$2:$P$400,"Done") -> 0 | D43: =IF($B$5=0,0,B43/$B$5) -> 4.375 | E43: =IF(D43>4.33,"Yes","") -> Yes
A44: 4 | B44: =SUMIFS(Plan!$N$2:$N$400,Plan!$B$2:$B$400,A44,Plan!$P$2:$P$400,"<>Skipped") -> 72 | C44: =SUMIFS(Plan!$N$2:$N$400,Plan!$B$2:$B$400,A44,Plan!$P$2:$P$400,"Done") -> 0 | D44: =IF($B$5=0,0,B44/$B$5) -> 4.5 | E44: =IF(D44>4.33,"Yes","") -> Yes
...

Sheet Plan
A1: Track | B1: Month | C1: Topic | D1: Depth target (what mastery looks like) | E1: Read | F1: Read URL | G1: Read cost | H1: Watch | I1: Watch URL | J1: Watch cost | K1: Do (lab / game / build) | L1: Do URL | M1: Do cost | N1: Hours | O1: Deliverable | P1: Status | Q1: Notes
A2: A. Linux, Networking, Shell | B2: 1 | C2: Shell mastery and scripting | D2: Write a 200-line bash tool with set -euo pipefail, traps, getopts, logging and tests, without looking anything up | E2: The Linux Command Line (William Shotts) | F2: https://linuxcommand.org/tlcl.php | G2: Free | H2: MIT The Missing Semester (lectures 1-5, 7) | I2: https://missing.csail.mit.edu/ | J2: Free | K2: OverTheWire Bandit (levels 0-33) | L2: https://overthewire.org/wargames/bandit/ | M2: Free | N2: 8 | O2: One research script rewritten as a hardened CLI with logs and a test | P2: Not started
A3: A. Linux, Networking, Shell | B3: 1 | C3: Linux internals: processes, systemd, permissions, filesystems, packaging | D3: Explain what happens from boot to a systemd service serving traffic; diagnose a stuck process from /proc | E3: Linux Journey (all of Grasshopper and Journeyman) | F3: https://linuxjourney.com/ | G3: Free | H3: freeCodeCamp: Linux Server Course, System Configuration and Operation | I3: https://www.youtube.com/@freecodecamp | J3: Free | K3: SadServers (scenarios, easy to medium) | L3: https://sadservers.com/ | M3: Free | N3: 8 | O3: Hardened Hetzner VPS with a systemd-managed Python service and a written boot-to-service explanation | P3: Not started
A4: A. Linux, Networking, Shell | B4: 1 | C4: Networking: TCP/IP, DNS, TLS, HTTP/2, load balancers, firewalls | D4: Trace a request from DNS to TLS handshake to response and name every hop; debug a failed webhook with tcpdump | E4: High Performance Browser Networking (ch 1-4, 12-13) | F4: https://hpbn.co/ | G4: Free | H4: Hussein Nasser: networking and backend fundamentals playlists | I4: https://www.youtube.com/@hnasr | J4: Free | K4: Protohackers (network programming challenges) | L4: https://protohackers.com/ | M4: Free | N4: 10 | O4: Three Protohackers problems solved in Python; one written webhook post-mortem using dig, curl -v, ss, tcpdump | P4: Not started
A5: A. Linux, Networking, Shell | B5: 1 | C5: Performance and troubleshooting on a single box | D5: Use the USE method; read top, vmstat, iostat, strace and perf output and say what is wrong | E5: Brendan Gregg: Linux Performance page and USE method | F5: https://www.brendangregg.com/linuxperf.html | G5: Free | H5: Brendan Gregg: Linux Performance Tools (talk) | I5: https://www.youtube.com/results?search_query=brendan+gregg+linux+performance+tools | J5: Free | K5: SadServers (hard scenarios) | L5: https://sadservers.com/ | M5: Free | N5: 5 | O5: Five hard SadServers scenarios solved with notes on the tool that found each cause | P5: Not started
A6: A. Linux, Networking, Shell | B6: 1 | C6: Git at depth: rebase, bisect, reflog, hooks, monorepo hygiene | D6: Recover a lost commit, bisect a regression, rewrite history safely | E6: Pro Git (ch 1-3, 7) | F6: https://git-scm.com/book/en/v2 | G6: Free | H6: Missing Semester: Version Control (git) lecture | I6: https://missing.csail.mit.edu/2020/version-control/ | J6: Free | K6: Learn Git Branching (all levels) | L6: https://learngitbranching.js.org/ | M6: Free | N6: 3 | O6: All Learn Git Branching levels done; a pre-commit hook running lint and tests on Dokeo | P6: Not started
A7: B. Containers and Kubernetes | B7: 1 | C7: Docker internals: namespaces, cgroups, layers, networking | D7: Explain a container without the word 'lightweight VM'; draw the layer cache; debug a bridge network issue | E7: Docker docs: Get started and Engine concepts | F7: https://docs.docker.com/get-started/ | G7: Free | H7: TechWorld with Nana: Docker Tutorial for Beginners (full course) | I7: https://www.youtube.com/@TechWorldwithNana | J7: Free | K7: Play with Docker | L7: https://labs.play-with-docker.com/ | M7: Free | N7: 8 | O7: One page explaining containers to a client CTO; a Compose stack for Dokeo with healthchecks | P7: Not started
A8: B. Containers and Kubernetes | B8: 1 | C8: Production images and supply chain: multi-stage, non-root, SBOM, scanning, signing | D8: Ship an image under 200 MB, non-root, zero HIGH CVEs, with an SBOM | E8: Docker: Building best practices | F8: https://docs.docker.com/build/building/best-practices/ | G8: Free | H8: Bret Fisher (Docker Captain) channel: image best practices | I8: https://www.youtube.com/@BretFisher | J8: Free | K8: Trivy (scan, SBOM) on your own images | L8: https://trivy.dev/ | M8: Free | N8: 6 | O8: Dokeo and DefenderMate images hardened; Trivy gate in CI | P8: Not started
A9: B. Containers and Kubernetes | B9: 1 | C9: Kubernetes core: Pod, Deployment, Service, Ingress, ConfigMap, Secret, namespaces | D9: Draw the object model from memory; explain how a request reaches a Pod through Ingress and Service | E9: Kubernetes docs: Concepts | F9: https://kubernetes.io/docs/concepts/ | G9: Free | H9: TechWorld with Nana: Kubernetes Tutorial for Beginners (full course) | I9: https://www.youtube.com/@TechWorldwithNana | J9: Free | K9: Killercoda Kubernetes scenarios | L9: https://killercoda.com/ | M9: Free | N9: 12 | O9: Dokeo on k3s (Hetzner) with Ingress, TLS, ConfigMap, Secret | P9: Not started
A10: B. Containers and Kubernetes | B10: 2 | C10: Kubernetes production ops: probes, HPA, requests and limits, storage, RBAC, NetworkPolicy, debugging | D10: Fix 'the pod won't start' in under ten minutes from describe, logs and events; roll back safely | E10: Linux Foundation LFS158: Introduction to Kubernetes | F10: https://training.linuxfoundation.org/training/introduction-to-kubernetes/ | G10: Free | H10: KodeKloud channel: CKA and troubleshooting videos | I10: https://www.youtube.com/@KodeKloud | J10: Free | K10: Killercoda CKA scenarios | L10: https://killercoda.com/ | M10: Free | N10: 12 | O10: Namespace per client, RBAC read-only role, NetworkPolicy isolating the DB, HPA, rollback drill recorded | P10: Not started
A11: B. Containers and Kubernetes | B11: 2 | C11: GitOps: Helm charts and ArgoCD | D11: A push to main updates the cluster; a bad change rolls back from Git | E11: ArgoCD docs: Getting started; Helm docs | F11: https://argo-cd.readthedocs.io/en/stable/getting_started/ | G11: Free | H11: TechWorld with Nana: ArgoCD and GitOps videos | I11: https://www.youtube.com/@TechWorldwithNana | J11: Free | K11: Deploy Dokeo via ArgoCD with your own Helm chart | L11: https://helm.sh/docs/ | M11: Free | N11: 8 | O11: Helm chart and ArgoCD app in a public repo | P11: Not started
A12: B. Containers and Kubernetes | B12: 2 | C12: Kubernetes security: Pod Security, RBAC, secrets, image policy, runtime | D12: Pass a Kubernetes Goat walkthrough and explain each finding to a client | E12: Kubernetes docs: Security + EKS Best Practices Guide (security) | F12: https://aws.github.io/aws-eks-best-practices/ | G12: Free | H12: CNCF channel: KubeCon security talks | I12: https://www.youtube.com/@cncf | J12: Free | K12: Kubernetes Goat (security playground) | L12: https://madhuakula.com/kubernetes-goat/ | M12: Free | N12: 6 | O12: Kubernetes Goat completed; a hardening checklist you'd hand a client | P12: Not started
A13: B. Containers and Kubernetes | B13: 2 | C13: Serving models on Kubernetes and GPUs | D13: Deploy vLLM on a GPU node, expose it behind your gateway, size it for 50 concurrent users | E13: vLLM docs: deployment and serving | F13: https://docs.vllm.ai/ | G13: Free | H13: Stanford CS336: Language Modeling from Scratch (inference lecture) | I13: https://stanford-cs336.github.io/ | J13: Free | K13: RunPod or similar GPU by the hour | L13: https://www.runpod.io/ | M13: Free tier | N13: 10 | O13: vLLM served open model with a benchmark table and a capacity plan | P13: Not started
... A79: L. Portfolio, Positioning, Pipeline | B79: 2 | C79: Public proof: three case studies and repos | D79: DefenderMate, Kaupex, Dokeo pages with architecture, what broke, what you'd change | E79: Design Docs at Google | F79: https://www.industrialempathy.com/posts/design-docs-at-google/ | G79: Free | H79: Write the Docs talks | I79: https://www.youtube.com/@WriteTheDocs | J79: Free | K79: Publish on rasul.in and GitHub | L79: https://github.com/rasulshaikh | M79: Free | N79: 12 | O79: Three case studies live | P79: Not started
A80: L. Portfolio, Positioning, Pipeline | B80: 3 | C80: Hermes write-up and LinkedIn positioning | D80: Profile reads Senior FDE, AI systems; one write-up shared by people who matter | E80: Your Hermes deployment | F80: https://github.com/NousResearch/hermes-agent | G80: Free | H80: n/a | J80: Free | K80: Publish and post | L80: https://www.linkedin.com/in/rasulshaikh | M80: Free | N80: 4 | O80: Write-up live; profile updated | P80: Not started
A81: L. Portfolio, Positioning, Pipeline | B81: 4 | C81: Target list: 40 companies, referrals, warm intros | D81: Forty companies with FDE roles that hire remote or in India, ranked by fit and comp; a referral path for 20 | E81: Aced guide company list + LinkedIn job search | F81: https://www.tryexponent.com/blog/forward-deployed-engineer-interview-the-definitive-2026-guide-fde | G81: Free | H81: n/a | J81: Free | K81: Tracker sheet with owner, status, next step | L81: https://www.linkedin.com/jobs/ | M81: Free | N81: 8 | O81: Target sheet with 40 rows | P81: Not started
A82: L. Portfolio, Positioning, Pipeline | B82: 6 | C82: Application pipeline: apply in waves, run three or four loops in parallel | D82: Two offers in the same two-week window | E82: Haseeb Qureshi negotiation rules | F82: https://haseebq.com/my-ten-rules-for-negotiating-a-job-offer/ | G82: Free | H82: n/a | J82: Free | K82: Weekly pipeline review | L82: https://www.linkedin.com/jobs/ | M82: Free | N82: 6 | O82: Pipeline tracker updated weekly | P82: Not started

Sheet Mocks
A1: Mock type | B1: Target count | C1: Hours each | D1: Month | E1: Where / how | F1: Pass bar | G1: Done so far | H1: Remaining | I1: Hours remaining
A2: Recruiter-screen narrative recordings | B2: 3 | C2: 1 | D2: 8 | E2: Self-recorded; review against the Aced guide | F2: Both 60-second answers land without hedging | G2: 0 | H2: =MAX(B2-G2,0) -> 3 | I2: =H2*C2 -> 3
A3: Technical screen (resume defence) | B3: 2 | C3: 1 | D3: 8 | E3: Peer mock on Exponent (free) or an ex-colleague | F3: Every bullet has a what-broke story | G3: 0 | H3: =MAX(B3-G3,0) -> 2 | I3: =H3*C3 -> 2
A4: Take-home builds (5h each, with video walkthrough) | B4: 4 | C4: 6 | D4: 9 | E4: Self-run on the clock; one reviewed by a senior engineer you trust | F4: Documented 70% shipped, tests pass, video under 10 minutes | G4: 0 | H4: =MAX(B4-G4,0) -> 4 | I4: =H4*C4 -> 24
A5: Decomposition / case study drills | B5: 10 | C5: 1 | D5: 9 | E5: Self-run from industry prompts; two with a peer playing the client | F5: Clarifying questions first, sized plan, one trade-off defended | G5: 0 | H5: =MAX(B5-G5,0) -> 10 | I5: =H5*C5 -> 10
A6: System design mocks (general) | B6: 6 | C6: 1.5 | D6: 6 | E6: Exponent peer mocks (free) | F6: 4/5 on the Hello Interview rubric three times running | G6: 0 | H6: =MAX(B6-G6,0) -> 6 | I6: =H6*C6 -> 9
A7: System design mocks (LLM-focused) | B7: 4 | C7: 2 | D7: 9 | E7: Exponent peer mocks; one with an FDE you find on LinkedIn | F7: Latency, cost, evals and fallbacks all covered unprompted | G7: 0 | H7: =MAX(B7-G7,0) -> 4 | I7: =H7*C7 -> 8
A8: Coding drills (data manipulation, AI-assisted build) | B8: 8 | C8: 1 | D8: 9 | E8: Timed on your own exports; narrate on video | F8: No silence; correct result in under 30 minutes | G8: 0 | H8: =MAX(B8-G8,0) -> 8 | I8: =H8*C8 -> 8
A9: Client simulations (hostile CFO, confused ops lead) | B9: 4 | C9: 1 | D9: 9 | E9: Friends or ex-colleagues in role; record | F9: Zero promises you could not keep | G9: 0 | H9: =MAX(B9-G9,0) -> 4 | I9: =H9*C9 -> 4
A10: Learning interviews (learn then apply in 20 min) | B10: 4 | C10: 0.5 | D10: 9 | E10: Pick an unfamiliar doc page; record | F10: Working example in 20 minutes | G10: 0 | H10: =MAX(B10-G10,0) -> 4 | I10: =H10*C10 -> 2
A11: Behavioural (STAR) sessions | B11: 10 | C11: 0.5 | D11: 9 | E11: Peer or self-recorded | F11: Each story under two minutes with a measurable outcome | G11: 0 | H11: =MAX(B11-G11,0) -> 10 | I11: =H11*C11 -> 5
A12: Full-loop simulations | B12: 2 | C12: 4 | D12: 9 | E12: interviewing.io (paid, optional) or a two-person peer panel | F12: Debrief written; weakest round identified and re-drilled | G12: 0 | H12: =MAX(B12-G12,0) -> 2 | I12: =H12*C12 -> 8
A13: Total | B13: =SUM(B2:B12) -> 57 | G13: =SUM(G2:G12) -> 0 | H13: =SUM(H2:H12) -> 57 | I13: =SUM(I2:I12) -> 83
A14: Edit only 'Done so far'. Mock hours are already inside the Plan hours for track K; this sheet tracks counts.

Sheet Roadmaps
A1: Roadmap or guide | B1: URL | C1: How to use it
A2: roadmap.sh: DevOps | B2: https://roadmap.sh/devops | C2: Self-check for tracks A-D; tick what you can do, not what you have read about
A3: roadmap.sh: Backend | B3: https://roadmap.sh/backend | C3: Self-check for track E
A4: roadmap.sh: AI Engineer | B4: https://roadmap.sh/ai-engineer | C4: Self-check for tracks G-H
A5: roadmap.sh: AI Agents | B5: https://roadmap.sh/ai-agents | C5: Agent patterns checklist
A6: roadmap.sh: System Design | B6: https://roadmap.sh/system-design | C6: Self-check for track F
A7: roadmap.sh: MLOps | B7: https://roadmap.sh/mlops | C7: Serving, monitoring, registries checklist
A8: Aced (Exponent): FDE interview definitive 2026 guide | B8: https://www.tryexponent.com/blog/forward-deployed-engineer-interview-the-definitive-2026-guide-fde | C8: Loop by company, 50+ questions, 6-week prep plan
A9: Aced: OpenAI, Databricks, Cognition FDE guides | B9: https://www.tryexponent.com/guides/openai-forward-deployed-engineer-interview | C9: Company-specific loops
A10: The FDE interview has six rounds (Medium, Jul 2026) | B10: https://medium.com/@shivanathd/the-forward-deployed-engineer-interview-has-six-rounds-365df0544e2c | C10: What each round scores
A11: fde.academy: FDE job descriptions explained | B11: https://fde.academy/blog/forward-deployed-engineer-job-description | C11: How to read a JD and spot a real FDE role
A12: Scaler AI FDE detailed curriculum (map only) | B12: https://www.scaler.com/scaler-ai-forward-deployed-engineer-detailed-curriculum | C12: Used as a topic map; every module is covered in this plan
A13: OneGTMLab FDE Skills Matrix (your upload) | C13: Ratings used to weight tracks J and K
A14: Palantir blog | B14: https://blog.palantir.com/ | C14: FDE culture, day-in-the-life posts
A15: Google SRE resources | B15: https://sre.google/ | C15: Reliability canon
A16: Hugging Face Learn | B16: https://huggingface.co/learn | C16: LLM, agents, and fine-tuning courses
A17: DeepLearning.AI short courses | B17: https://www.deeplearning.ai/short-courses/ | C17: One-hour courses on RAG, evals, agents, APIs

Sheet CompReality
A1: Market | B1: Band | C1: Source | D1: What it takes | E1: Probability in 9 months (my read)
A2: United States, FDE, base | B2: $110,000 to $180,000 base; senior total comp above $200,000 | C2: fde.academy salary guide (Feb 2026) | D2: On-site or US-remote; visa or relocation for you | E2: Low in 9 months without relocation
A3: AI labs and top startups (global) | B3: $180,000 to $550,000 total comp depending on experience, company and location | C3: taggd.in FDE guide (May 2026) | D3: Lab-grade loop; usually US-based; travel | E3: Very low in 9 months; realistic at 24-36 months after one US-market FDE role
A4: India, global-remote senior FDE | B4: Roughly ₹55 to 90 LPA or more for senior and global-remote India roles | C4: OwnYourCareer / buildfastwithai bands (Jun-Jul 2026) | D4: Remote-first US or EU company paying dollar-linked; strong public proof | E4: Realistic in 6-9 months with this plan
A5: India, domestic AI startups and GCCs | B5: ₹28 to 55 LPA at 3-6 years | C5: OwnYourCareer bands (Jun 2026) | D5: Standard loop; India presence | E5: High in 3-6 months
A6: UAE, senior AI or FDE-type roles | B6: Typical AED 25,000 to 45,000 per month; senior GenAI AED 450,000 to 600,000+ per year; tax free | C6: jobxdubai (Michael Page 2026) and jobseekers.ae (Jan 2026) | D6: Relocation, employer visa; G42, Hub71 startups, sovereign employers at the top | E6: Moderate in 9-12 months with relocation; $250K (about AED 918,000) is top-of-market and rare
A7: Your $250K target | B7: About ₹2.1 crore, €215,000, or AED 918,000 per year | C7: Conversion, Sep 2026 | D7: US lab or top startup on-site, or a UAE sovereign-tier employer, plus Senior-level proof | E7: Not a 9-month target from Pune; a 2-3 year target with one US-market FDE role in between
A9: Bands are public estimates gathered September 2026 and vary widely by employer; treat them as anchors for negotiation, not promises. Probability column is my judgment, not data.
